Workbook
Name USD_BDT: Settings!$B$5
Name RMB_BDT: Settings!$B$6
Name CUSTOMS_PCT: Settings!$B$7
Name MISC_FEE: Settings!$B$8
Name MARKUP_PCT: Settings!$B$9
Name MAX_PRICE: Settings!$B$10
Name HARD_REJECT_PRICE: Settings!$B$11
Name W_FEMININE: Settings!$B$12
Name W_TREND: Settings!$B$13
Name W_AESTHETIC: Settings!$B$14
Name W_STYLE: Settings!$B$15
Name W_LIGHT: Settings!$B$16
Name W_REELS: Settings!$B$17
Name W_GIFT: Settings!$B$18
Name W_PRICEFIT: Settings!$B$19
Name W_DEMAND: Settings!$B$20
Name W_QUALITY: Settings!$B$21
Name BUY_THRESHOLD: Settings!$B$22
Name MAYBE_THRESHOLD: Settings!$B$23
Name LOW_PROFIT_PCT: Settings!$B$24
Name MOQ_WARNING: Settings!$B$25
Name MONTHLY_BUDGET: Settings!$B$26
Name LIST_PLATFORM: 'Dropdown Lists'!$A$2:$A$7
Name LIST_CATEGORY: 'Dropdown Lists'!$B$2:$B$14
Name LIST_CURRENCY: 'Dropdown Lists'!$C$2:$C$4
Name LIST_DECISION: 'Dropdown Lists'!$D$2:$D$5
Name LIST_APPROVAL: 'Dropdown Lists'!$E$2:$E$5
Name LIST_SCORE: 'Dropdown Lists'!$F$2:$F$6
Name LIST_YESNO: 'Dropdown Lists'!$G$2:$G$3
Name LIST_LEVEL: 'Dropdown Lists'!$H$2:$H$4
Name LIST_PACKAGING: 'Dropdown Lists'!$I$2:$I$4
Name LIST_SOURCING_STATUS: 'Dropdown Lists'!$J$2:$J$10
Name LIST_QC_STATUS: 'Dropdown Lists'!$K$2:$K$8
Name LIST_AI_TOOL: 'Dropdown Lists'!$L$2:$L$5
Name CATEGORY_PREFIX_TABLE: 'Dropdown Lists'!$M$2:$N$14

Sheet Product Tracker
A1: AAYNA Product Scout Lite — Product Tracker | I1: Reflect your everyday style — sourcing decisions, made together.
A2: SKU | B2: Date Added | C2: Product Name | D2: Product Image/Link | E2: Category | F2: Source Platform | G2: Source URL | H2: Supplier Name | I2: Unit Cost (Source Currency) | J2: Source Currency | K2: Unit Cost (BDT) | L2: Shipping Cost/Unit (BDT) | M2: Customs/Duty % | N2: Misc Fees/Unit (BDT) | O2: Estimated Landed Cost (BDT) | P2: Suggested Selling Price (BDT) | Q2: Expected Profit/Unit (BDT) | R2: Profit Margin % | S2: Feminine Score (1-5) | T2: Trend Score (1-5) | U2: AAYNA Aesthetic Fit Score (1-5) | V2: Easy to Style Score (1-5) | W2: Lightweight Score (1-5) | X2: Reels/Photo Potential Score (1-5) | Y2: Giftability Score (1-5) | Z2: Price Fit Score (1-5) | AA2: Demand Score (1-5) | AB2: Quality/Risk Score (1-5) | AC2: Total Product Score (/100) | AD2: Decision | AE2: Reason | AF2: Content/Reel Idea | AG2: Approval Status | AH2: Approved By | AI2: Date Decided | AJ2: Rank Key: Overall (hidden) | AK2: Rank Key: Under 700 BDT (hidden) | AL2: Rank Key: Reels/Photo (hidden) | AM2: Rank Key: Giftability (hidden) | AN2: Rank Key: Needs Review (hidden) | AO2: Supplier Rating | AP2: Product Rating | AQ2: Sold Count / Order Count | AR2: Review Count | AS2: Real Review Photos? | AT2: MOQ | AU2: Recommended Test Quantity | AV2: Final Approved Quantity | AW2: Total Purchase Cost (BDT) | AX2: Weight / Size | AY2: Fragility Level | AZ2: Packaging Difficulty | BA2: Courier Risk | BB2: Duplicate Found on BD Market? | BC2: Competitor Price (BDT) | BD2: Market Saturation Level | BE2: Auto Flag / Warning | BF2: Sourcing Status | BG2: Product Name Finalized? | BH2: SKU Finalized? | BI2: Photos Ready? | BJ2: Description Ready? | BK2: Price Approved? | BL2: Ready for Website Upload? | BM2: Actual Product Cost (BDT) | BN2: Actual Shipping Cost (BDT) | BO2: Actual Landed Cost (BDT) | BP2: Actual Selling Price (BDT) | BQ2: Actual Profit (BDT) | BR2: Actual Profit Margin | BS2: Arrival Date | BT2: Quantity Received | BU2: Defect Count | BV2: QC Status | BW2: QC Notes | BX2: Final Stock Accepted | BY2: AI Tool Used | BZ2: AI Score Date | CA2: Scored By | CB2: Manual Score Adjusted?
A3: =IF(C3="","","AYN-"&IFERROR(VLOOKUP(E3,CATEGORY_PREFIX_TABLE,2,FALSE),"OTH")&"-"&TEXT(ROW()-2,"0000")) | B3: 2026-06-20 | C3: Antique Gold Hoop Earrings | D3: drive.google.com/sample1 | E3: Earrings | F3: AliExpress | G3: aliexpress.com/item/sample1 | H3: Lin Wei Trading | I3: 1.8 | J3: USD | K3: =IF(I3="","",IF(J3="BDT",I3,IF(J3="USD",I3*USD_BDT,IF(J3="RMB",I3*RMB_BDT,"")))) | L3: 25 | N3: 15 | O3: =IF(K3="","",K3+IFERROR(L3,0)+(K3*IF(M3="",CUSTOMS_PCT,M3))+IF(N3="",MISC_FEE,N3)) | P3: =IF(O3="","",ROUND(O3*(1+MARKUP_PCT),-1)-1) | Q3: =IF(P3="","",P3-O3) | R3: =IF(OR(P3="",P3=0),"",Q3/P3) | S3: 5 | T3: 5 | U3: 5 | V3: 4 | W3: 5 | X3: 5 | Y3: 4 | Z3: 5 | AA3: 4 | AB3: 5 | AC3: =IF(COUNT(S3:AB3)<10,"",(S3*W_FEMININE+T3*W_TREND+U3*W_AESTHETIC+V3*W_STYLE+W3*W_LIGHT+X3*W_REELS+Y3*W_GIFT+Z3*W_PRICEFIT+AA3*W_DEMAND+AB3*W_QUALITY)/5*100) | AD3: =IF(P3="","",IF(P3>HARD_REJECT_PRICE,"Reject",IF(P3>MAX_PRICE,"Price Review",IF(AC3="","",IF(AND(AC3>=BUY_THRESHOLD,OR(AB3<=2,U3<=2)),"Maybe",IF(AC3>=BUY_THRESHOLD,"Buy",IF(AC3>=MAYBE_THRESHOLD,"Maybe","Reject"))))))) | AE3: Strong rose-gold match, trending on TikTok, lightweight and giftable. | AF3: Reel: 'Get Ready With Me' earring swap, 3 looks in 15 sec. | AG3: Approved | AH3: Nadia | AI3: 2026-06-21 | AJ3: =IF(AC3="",-9999-ROW()*0.0000001,AC3-ROW()*0.0000001) | AK3: =IF(OR(AC3="",P3="",P3>MAX_PRICE),-9999-ROW()*0.0000001,AC3-ROW()*0.0000001) | AL3: =IF(AC3="",-9999-ROW()*0.0000001,X3*1000+AC3-ROW()*0.0000001) | AM3: =IF(AC3="",-9999-ROW()*0.0000001,Y3*1000+AC3-ROW()*0.0000001) | AN3: =IF(AND(OR(AD3="Maybe",AD3="Price Review"),AG3<>"Approved",AG3<>"Rejected"),IF(AC3="",0,AC3)-ROW()*0.0000001,-9999-ROW()*0.0000001) | AO3: 4.8 | AP3: 4.7 | AQ3: 1200 | AR3: 340 | AS3: Yes | AT3: 20 | AU3: 30 | AV3: 50 | AW3: =IF(OR(O3="",AV3=""),"",O3*AV3) | AX3: 15g, 3 x 4 cm | AY3: Low | AZ3: Easy | BA3: Low | BB3: No | BC3: 650 | BD3: Low | BE3: =IF(C3="","",IF(AND(ISNUMBER(P3),P3>MAX_PRICE),"Price too high",IF(AND(ISNUMBER(AB3),AB3<=2),"Quality risk",IF(AND(ISNUMBER(U3),U3<=2),"Aesthetic mismatch",IF(AY3="High","Too fragile",IF(AND(ISNUMBER(R3),R3<LOW_PROFIT_PCT),"Low profit",IF(AND(ISNUMBER(AT3),AT3>MOQ_WARNING),"MOQ too high",IF(OR(AD3="Maybe",AD3="Price Review"),"Needs partner review",IF(AD3="Buy","Good candidate",""))))))))) | BF3: Approved - Not Ordered | BG3: Yes | BH3: Yes | BI3: Yes | BJ3: Yes | BK3: Yes | BL3: =IF(C3="","",IF(AND(BG3="Yes",BH3="Yes",BI3="Yes",BJ3="Yes",BK3="Yes"),"Yes","No")) | BO3: =IF(OR(BM3="",BN3=""),"",BM3+BN3) | BQ3: =IF(OR(BP3="",BO3=""),"",BP3-BO3) | BR3: =IF(OR(BP3="",BP3=0,BQ3=""),"",BQ3/BP3) | BV3: Not Arrived | BX3: =IF(OR(BT3="",BU3=""),"",BT3-BU3) | BY3: Claude | BZ3: 2026-06-20 | CA3: Nadia | CB3: No
A4: =IF(C4="","","AYN-"&IFERROR(VLOOKUP(E4,CATEGORY_PREFIX_TABLE,2,FALSE),"OTH")&"-"&TEXT(ROW()-2,"0000")) | B4: 2026-06-21 | C4: Beaded Choker Necklace | D4: drive.google.com/sample2 | E4: Necklace | F4: SkyBuyBD | G4: skybuybd.com/item/sample2 | H4: Skybuy Supplier 14 | I4: 60 | J4: BDT | K4: =IF(I4="","",IF(J4="BDT",I4,IF(J4="USD",I4*USD_BDT,IF(J4="RMB",I4*RMB_BDT,"")))) | L4: 10 | N4: 12 | O4: =IF(K4="","",K4+IFERROR(L4,0)+(K4*IF(M4="",CUSTOMS_PCT,M4))+IF(N4="",MISC_FEE,N4)) | P4: =IF(O4="","",ROUND(O4*(1+MARKUP_PCT),-1)-1) | Q4: =IF(P4="","",P4-O4) | R4: =IF(OR(P4="",P4=0),"",Q4/P4) | S4: 5 | T4: 4 | U4: 5 | V4: 4 | W4: 4 | X4: 4 | Y4: 4 | Z4: 5 | AA4: 4 | AB4: 2 | AC4: =IF(COUNT(S4:AB4)<10,"",(S4*W_FEMININE+T4*W_TREND+U4*W_AESTHETIC+V4*W_STYLE+W4*W_LIGHT+X4*W_REELS+Y4*W_GIFT+Z4*W_PRICEFIT+AA4*W_DEMAND+AB4*W_QUALITY)/5*100) | AD4: =IF(P4="","",IF(P4>HARD_REJECT_PRICE,"Reject",IF(P4>MAX_PRICE,"Price Review",IF(AC4="","",IF(AND(AC4>=BUY_THRESHOLD,OR(AB4<=2,U4<=2)),"Maybe",IF(AC4>=BUY_THRESHOLD,"Buy",IF(AC4>=MAYBE_THRESHOLD,"Maybe","Reject"))))))) | AE4: Gorgeous and on-trend, but beads chip easily in transit — quality/return risk caps this at Maybe. | AF4: Try-on reel layering 3 chokers. | AG4: Pending | AJ4: =IF(AC4="",-9999-ROW()*0.0000001,AC4-ROW()*0.0000001) | AK4: =IF(OR(AC4="",P4="",P4>MAX_PRICE),-9999-ROW()*0.0000001,AC4-ROW()*0.0000001) | AL4: =IF(AC4="",-9999-ROW()*0.0000001,X4*1000+AC4-ROW()*0.0000001) | AM4: =IF(AC4="",-9999-ROW()*0.0000001,Y4*1000+AC4-ROW()*0.0000001) | AN4: =IF(AND(OR(AD4="Maybe",AD4="Price Review"),AG4<>"Approved",AG4<>"Rejected"),IF(AC4="",0,AC4)-ROW()*0.0000001,-9999-ROW()*0.0000001) | AO4: 4.3 | AP4: 4.1 | AQ4: 650 | AR4: 180 | AS4: Yes | AT4: 30 | AU4: 20 | AW4: =IF(OR(O4="",AV4=""),"",O4*AV4) | AX4: 25g, one size | AY4: Medium | AZ4: Medium | BA4: Medium | BB4: Yes | BC4: 80 | BD4: Medium | BE4: =IF(C4="","",IF(AND(ISNUMBER(P4),P4>MAX_PRICE),"Price too high",IF(AND(ISNUMBER(AB4),AB4<=2),"Quality risk",IF(AND(ISNUMBER(U4),U4<=2),"Aesthetic mismatch",IF(AY4="High","Too fragile",IF(AND(ISNUMBER(R4),R4<LOW_PROFIT_PCT),"Low profit",IF(AND(ISNUMBER(AT4),AT4>MOQ_WARNING),"MOQ too high",IF(OR(AD4="Maybe",AD4="Price Review"),"Needs partner review",IF(AD4="Buy","Good candidate",""))))))))) | BF4: Sample Ordered | BL4: =IF(C4="","",IF(AND(BG4="Yes",BH4="Yes",BI4="Yes",BJ4="Yes",BK4="Yes"),"Yes","No")) | BO4: =IF(OR(BM4="",BN4=""),"",BM4+BN4) | BQ4: =IF(OR(BP4="",BO4=""),"",BP4-BO4) | BR4: =IF(OR(BP4="",BP4=0,BQ4=""),"",BQ4/BP4) | BV4: Not Arrived | BX4: =IF(OR(BT4="",BU4=""),"",BT4-BU4) | BY4: ChatGPT | BZ4: 2026-06-21 | CA4: Imran | CB4: Yes
A5: =IF(C5="","","AYN-"&IFERROR(VLOOKUP(E5,CATEGORY_PREFIX_TABLE,2,FALSE),"OTH")&"-"&TEXT(ROW()-2,"0000")) | B5: 2026-06-21 | C5: Plain Plastic Hair Clip | D5: drive.google.com/sample3 | E5: Hair Accessory | F5: 1688 | G5: 1688.com/item/sample3 | H5: Generic Factory 8 | I5: 25 | J5: BDT | K5: =IF(I5="","",IF(J5="BDT",I5,IF(J5="USD",I5*USD_BDT,IF(J5="RMB",I5*RMB_BDT,"")))) | L5: 8 | N5: 10 | O5: =IF(K5="","",K5+IFERROR(L5,0)+(K5*IF(M5="",CUSTOMS_PCT,M5))+IF(N5="",MISC_FEE,N5)) | P5: =IF(O5="","",ROUND(O5*(1+MARKUP_PCT),-1)-1) | Q5: =IF(P5="","",P5-O5) | R5: =IF(OR(P5="",P5=0),"",Q5/P5) | S5: 2 | T5: 2 | U5: 2 | V5: 3 | W5: 3 | X5: 2 | Y5: 2 | Z5: 4 | AA5: 2 | AB5: 3 | AC5: =IF(COUNT(S5:AB5)<10,"",(S5*W_FEMININE+T5*W_TREND+U5*W_AESTHETIC+V5*W_STYLE+W5*W_LIGHT+X5*W_REELS+Y5*W_GIFT+Z5*W_PRICEFIT+AA5*W_DEMAND+AB5*W_QUALITY)/5*100) | AD5: =IF(P5="","",IF(P5>HARD_REJECT_PRICE,"Reject",IF(P5>MAX_PRICE,"Price Review",IF(AC5="","",IF(AND(AC5>=BUY_THRESHOLD,OR(AB5<=2,U5<=2)),"Maybe",IF(AC5>=BUY_THRESHOLD,"Buy",IF(AC5>=MAYBE_THRESHOLD,"Maybe","Reject"))))))) | AE5: Generic look, low trend/demand/aesthetic fit — total score too low to justify stocking. | AG5: Rejected | AJ5: =IF(AC5="",-9999-ROW()*0.0000001,AC5-ROW()*0.0000001) | AK5: =IF(OR(AC5="",P5="",P5>MAX_PRICE),-9999-ROW()*0.0000001,AC5-ROW()*0.0000001) | AL5: =IF(AC5="",-9999-ROW()*0.0000001,X5*1000+AC5-ROW()*0.0000001) | AM5: =IF(AC5="",-9999-ROW()*0.0000001,Y5*1000+AC5-ROW()*0.0000001) | AN5: =IF(AND(OR(AD5="Maybe",AD5="Price Review"),AG5<>"Approved",AG5<>"Rejected"),IF(AC5="",0,AC5)-ROW()*0.0000001,-9999-ROW()*0.0000001) | AO5: 3.2 | AP5: 3 | AQ5: 2200 | AR5: 90 | AS5: No | AT5: 80 | AW5: =IF(OR(O5="",AV5=""),"",O5*AV5) | AX5: 5g, 6 cm clip | AY5: Low | AZ5: Easy | BA5: Low | BB5: Yes | BC5: 15 | BD5: High | BE5: =IF(C5="","",IF(AND(ISNUMBER(P5),P5>MAX_PRICE),"Price too high",IF(AND(ISNUMBER(AB5),AB5<=2),"Quality risk",IF(AND(ISNUMBER(U5),U5<=2),"Aesthetic mismatch",IF(AY5="High","Too fragile",IF(AND(ISNUMBER(R5),R5<LOW_PROFIT_PCT),"Low profit",IF(AND(ISNUMBER(AT5),AT5>MOQ_WARNING),"MOQ too high",IF(OR(AD5="Maybe",AD5="Price Review"),"Needs partner review",IF(AD5="Buy","Good candidate",""))))))))) | BF5: Not Started | BL5: =IF(C5="","",IF(AND(BG5="Yes",BH5="Yes",BI5="Yes",BJ5="Yes",BK5="Yes"),"Yes","No")) | BO5: =IF(OR(BM5="",BN5=""),"",BM5+BN5) | BQ5: =IF(OR(BP5="",BO5=""),"",BP5-BO5) | BR5: =IF(OR(BP5="",BP5=0,BQ5=""),"",BQ5/BP5) | BV5: Not Arrived | BX5: =IF(OR(BT5="",BU5=""),"",BT5-BU5) | BY5: Claude | BZ5: 2026-06-21 | CA5: Nadia | CB5: No
A6: =IF(C6="","","AYN-"&IFERROR(VLOOKUP(E6,CATEGORY_PREFIX_TABLE,2,FALSE),"OTH")&"-"&TEXT(ROW()-2,"0000")) | B6: 2026-06-22 | C6: Embroidered Tote Bag | D6: drive.google.com/sample4 | E6: Bag | F6: AliExpress | G6: aliexpress.com/item/sample4 | H6: Lin Wei Trading | I6: 300 | J6: BDT | K6: =IF(I6="","",IF(J6="BDT",I6,IF(J6="USD",I6*USD_BDT,IF(J6="RMB",I6*RMB_BDT,"")))) | L6: 40 | N6: 15 | O6: =IF(K6="","",K6+IFERROR(L6,0)+(K6*IF(M6="",CUSTOMS_PCT,M6))+IF(N6="",MISC_FEE,N6)) | P6: =IF(O6="","",ROUND(O6*(1+MARKUP_PCT),-1)-1) | Q6: =IF(P6="","",P6-O6) | R6: =IF(OR(P6="",P6=0),"",Q6/P6) | S6: 4 | T6: 4 | U6: 4 | V6: 3 | W6: 3 | X6: 3 | Y6: 4 | Z6: 2 | AA6: 4 | AB6: 4 | AC6: =IF(COUNT(S6:AB6)<10,"",(S6*W_FEMININE+T6*W_TREND+U6*W_AESTHETIC+V6*W_STYLE+W6*W_LIGHT+X6*W_REELS+Y6*W_GIFT+Z6*W_PRICEFIT+AA6*W_DEMAND+AB6*W_QUALITY)/5*100) | AD6: =IF(P6="","",IF(P6>HARD_REJECT_PRICE,"Reject",IF(P6>MAX_PRICE,"Price Review",IF(AC6="","",IF(AND(AC6>=BUY_THRESHOLD,OR(AB6<=2,U6<=2)),"Maybe",IF(AC6>=BUY_THRESHOLD,"Buy",IF(AC6>=MAYBE_THRESHOLD,"Maybe","Reject"))))))) | AE6: Lovely design, but landed cost pushes selling price over 700 — needs supplier price negotiation. | AF6: Flatlay reel with 3 outfit pairings. | AG6: Pending | AJ6: =IF(AC6="",-9999-ROW()*0.0000001,AC6-ROW()*0.0000001) | AK6: =IF(OR(AC6="",P6="",P6>MAX_PRICE),-9999-ROW()*0.0000001,AC6-ROW()*0.0000001) | AL6: =IF(AC6="",-9999-ROW()*0.0000001,X6*1000+AC6-ROW()*0.0000001) | AM6: =IF(AC6="",-9999-ROW()*0.0000001,Y6*1000+AC6-ROW()*0.0000001) | AN6: =IF(AND(OR(AD6="Maybe",AD6="Price Review"),AG6<>"Approved",AG6<>"Rejected"),IF(AC6="",0,AC6)-ROW()*0.0000001,-9999-ROW()*0.0000001) | AO6: 4.5 | AP6: 4.2 | AQ6: 300 | AR6: 75 | AS6: Yes | AT6: 40 | AU6: 15 | AW6: =IF(OR(O6="",AV6=""),"",O6*AV6) | AX6: 320g, 30 x 35 cm | AY6: Low | AZ6: Medium | BA6: Medium | BB6: No | BC6: 720 | BD6: Low | BE6: =IF(C6="","",IF(AND(ISNUMBER(P6),P6>MAX_PRICE),"Price too high",IF(AND(ISNUMBER(AB6),AB6<=2),"Quality risk",IF(AND(ISNUMBER(U6),U6<=2),"Aesthetic mismatch",IF(AY6="High","Too fragile",IF(AND(ISNUMBER(R6),R6<LOW_PROFIT_PCT),"Low profit",IF(AND(ISNUMBER(AT6),AT6>MOQ_WARNING),"MOQ too high",IF(OR(AD6="Maybe",AD6="Price Review"),"Needs partner review",IF(AD6="Buy","Good candidate",""))))))))) | BF6: Sourcing | BG6: Yes | BH6: Yes | BL6: =IF(C6="","",IF(AND(BG6="Yes",BH6="Yes",BI6="Yes",BJ6="Yes",BK6="Yes"),"Yes","No")) | BO6: =IF(OR(BM6="",BN6=""),"",BM6+BN6) | BQ6: =IF(OR(BP6="",BO6=""),"",BP6-BO6) | BR6: =IF(OR(BP6="",BP6=0,BQ6=""),"",BQ6/BP6) | BV6: Not Arrived | BX6: =IF(OR(BT6="",BU6=""),"",BT6-BU6) | BY6: Gemini | BZ6: 2026-06-22 | CA6: Imran | CB6: No
A7: =IF(C7="","","AYN-"&IFERROR(VLOOKUP(E7,CATEGORY_PREFIX_TABLE,2,FALSE),"OTH")&"-"&TEXT(ROW()-2,"0000")) | B7: 2026-06-22 | C7: Designer-Inspired Sunglasses | D7: drive.google.com/sample5 | E7: Sunglasses | F7: AliExpress | G7: aliexpress.com/item/sample5 | H7: Guangzhou Eyewear Co | I7: 15 | J7: USD | K7: =IF(I7="","",IF(J7="BDT",I7,IF(J7="USD",I7*USD_BDT,IF(J7="RMB",I7*RMB_BDT,"")))) | L7: 50 | N7: 15 | O7: =IF(K7="","",K7+IFERROR(L7,0)+(K7*IF(M7="",CUSTOMS_PCT,M7))+IF(N7="",MISC_FEE,N7)) | P7: =IF(O7="","",ROUND(O7*(1+MARKUP_PCT),-1)-1) | Q7: =IF(P7="","",P7-O7) | R7: =IF(OR(P7="",P7=0),"",Q7/P7) | AC7: =IF(COUNT(S7:AB7)<10,"",(S7*W_FEMININE+T7*W_TREND+U7*W_AESTHETIC+V7*W_STYLE+W7*W_LIGHT+X7*W_REELS+Y7*W_GIFT+Z7*W_PRICEFIT+AA7*W_DEMAND+AB7*W_QUALITY)/5*100) | AD7: =IF(P7="","",IF(P7>HARD_REJECT_PRICE,"Reject",IF(P7>MAX_PRICE,"Price Review",IF(AC7="","",IF(AND(AC7>=BUY_THRESHOLD,OR(AB7<=2,U7<=2)),"Maybe",IF(AC7>=BUY_THRESHOLD,"Buy",IF(AC7>=MAYBE_THRESHOLD,"Maybe","Reject"))))))) | AE7: Cost alone puts this far above our price ceiling even before scoring — auto-rejected. | AG7: Rejected | AJ7: =IF(AC7="",-9999-ROW()*0.0000001,AC7-ROW()*0.0000001) | AK7: =IF(OR(AC7="",P7="",P7>MAX_PRICE),-9999-ROW()*0.0000001,AC7-ROW()*0.0000001) | AL7: =IF(AC7="",-9999-ROW()*0.0000001,X7*1000+AC7-ROW()*0.0000001) | AM7: =IF(AC7="",-9999-ROW()*0.0000001,Y7*1000+AC7-ROW()*0.0000001) | AN7: =IF(AND(OR(AD7="Maybe",AD7="Price Review"),AG7<>"Approved",AG7<>"Rejected"),IF(AC7="",0,AC7)-ROW()*0.0000001,-9999-ROW()*0.0000001) | AO7: 3.8 | AP7: 3.5 | AQ7: 900 | AR7: 210 | AS7: No | AT7: 60 | AW7: =IF(OR(O7="",AV7=""),"",O7*AV7) | AX7: 28g, with case | AY7: High | AZ7: Hard | BA7: High | BB7: Yes | BC7: 450 | BD7: High | BE7: =IF(C7="","",IF(AND(ISNUMBER(P7),P7>MAX_PRICE),"Price too high",IF(AND(ISNUMBER(AB7),AB7<=2),"Quality risk",IF(AND(ISNUMBER(U7),U7<=2),"Aesthetic mismatch",IF(AY7="High","Too fragile",IF(AND(ISNUMBER(R7),R7<LOW_PROFIT_PCT),"Low profit",IF(AND(ISNUMBER(AT7),AT7>MOQ_WARNING),"MOQ too high",IF(OR(AD7="Maybe",AD7="Price Review"),"Needs partner review",IF(AD7="Buy","Good candidate",""))))))))) | BF7: Not Started | BL7: =IF(C7="","",IF(AND(BG7="Yes",BH7="Yes",BI7="Yes",BJ7="Yes",BK7="Yes"),"Yes","No")) | BO7: =IF(OR(BM7="",BN7=""),"",BM7+BN7) | BQ7: =IF(OR(BP7="",BO7=""),"",BP7-BO7) | BR7: =IF(OR(BP7="",BP7=0,BQ7=""),"",BQ7/BP7) | BV7: Not Arrived | BX7: =IF(OR(BT7="",BU7=""),"",BT7-BU7) | BY7: ChatGPT | BZ7: 2026-06-22 | CA7: Nadia | CB7: No
A8: =IF(C8="","","AYN-"&IFERROR(VLOOKUP(E8,CATEGORY_PREFIX_TABLE,2,FALSE),"OTH")&"-"&TEXT(ROW()-2,"0000")) | K8: =IF(I8="","",IF(J8="BDT",I8,IF(J8="USD",I8*USD_BDT,IF(J8="RMB",I8*RMB_BDT,"")))) | O8: =IF(K8="","",K8+IFERROR(L8,0)+(K8*IF(M8="",CUSTOMS_PCT,M8))+IF(N8="",MISC_FEE,N8)) | P8: =IF(O8="","",ROUND(O8*(1+MARKUP_PCT),-1)-1) | Q8: =IF(P8="","",P8-O8) | R8: =IF(OR(P8="",P8=0),"",Q8/P8) | AC8: =IF(COUNT(S8:AB8)<10,"",(S8*W_FEMININE+T8*W_TREND+U8*W_AESTHETIC+V8*W_STYLE+W8*W_LIGHT+X8*W_REELS+Y8*W_GIFT+Z8*W_PRICEFIT+AA8*W_DEMAND+AB8*W_QUALITY)/5*100) | AD8: =IF(P8="","",IF(P8>HARD_REJECT_PRICE,"Reject",IF(P8>MAX_PRICE,"Price Review",IF(AC8="","",IF(AND(AC8>=BUY_THRESHOLD,OR(AB8<=2,U8<=2)),"Maybe",IF(AC8>=BUY_THRESHOLD,"Buy",IF(AC8>=MAYBE_THRESHOLD,"Maybe","Reject"))))))) | AJ8: =IF(AC8="",-9999-ROW()*0.0000001,AC8-ROW()*0.0000001) | AK8: =IF(OR(AC8="",P8="",P8>MAX_PRICE),-9999-ROW()*0.0000001,AC8-ROW()*0.0000001) | AL8: =IF(AC8="",-9999-ROW()*0.0000001,X8*1000+AC8-ROW()*0.0000001) | AM8: =IF(AC8="",-9999-ROW()*0.0000001,Y8*1000+AC8-ROW()*0.0000001) | AN8: =IF(AND(OR(AD8="Maybe",AD8="Price Review"),AG8<>"Approved",AG8<>"Rejected"),IF(AC8="",0,AC8)-ROW()*0.0000001,-9999-ROW()*0.0000001) | AW8: =IF(OR(O8="",AV8=""),"",O8*AV8) | BE8: =IF(C8="","",IF(AND(ISNUMBER(P8),P8>MAX_PRICE),"Price too high",IF(AND(ISNUMBER(AB8),AB8<=2),"Quality risk",IF(AND(ISNUMBER(U8),U8<=2),"Aesthetic mismatch",IF(AY8="High","Too fragile",IF(AND(ISNUMBER(R8),R8<LOW_PROFIT_PCT),"Low profit",IF(AND(ISNUMBER(AT8),AT8>MOQ_WARNING),"MOQ too high",IF(OR(AD8="Maybe",AD8="Price Review"),"Needs partner review",IF(AD8="Buy","Good candidate",""))))))))) | BL8: =IF(C8="","",IF(AND(BG8="Yes",BH8="Yes",BI8="Yes",BJ8="Yes",BK8="Yes"),"Yes","No")) | BO8: =IF(OR(BM8="",BN8=""),"",BM8+BN8) | BQ8: =IF(OR(BP8="",BO8=""),"",BP8-BO8) | BR8: =IF(OR(BP8="",BP8=0,BQ8=""),"",BQ8/BP8) | BX8: =IF(OR(BT8="",BU8=""),"",BT8-BU8)
A9: =IF(C9="","","AYN-"&IFERROR(VLOOKUP(E9,CATEGORY_PREFIX_TABLE,2,FALSE),"OTH")&"-"&TEXT(ROW()-2,"0000")) | K9: =IF(I9="","",IF(J9="BDT",I9,IF(J9="USD",I9*USD_BDT,IF(J9="RMB",I9*RMB_BDT,"")))) | O9: =IF(K9="","",K9+IFERROR(L9,0)+(K9*IF(M9="",CUSTOMS_PCT,M9))+IF(N9="",MISC_FEE,N9)) | P9: =IF(O9="","",ROUND(O9*(1+MARKUP_PCT),-1)-1) | Q9: =IF(P9="","",P9-O9) | R9: =IF(OR(P9="",P9=0),"",Q9/P9) | AC9: =IF(COUNT(S9:AB9)<10,"",(S9*W_FEMININE+T9*W_TREND+U9*W_AESTHETIC+V9*W_STYLE+W9*W_LIGHT+X9*W_REELS+Y9*W_GIFT+Z9*W_PRICEFIT+AA9*W_DEMAND+AB9*W_QUALITY)/5*100) | AD9: =IF(P9="","",IF(P9>HARD_REJECT_PRICE,"Reject",IF(P9>MAX_PRICE,"Price Review",IF(AC9="","",IF(AND(AC9>=BUY_THRESHOLD,OR(AB9<=2,U9<=2)),"Maybe",IF(AC9>=BUY_THRESHOLD,"Buy",IF(AC9>=MAYBE_THRESHOLD,"Maybe","Reject"))))))) | AJ9: =IF(AC9="",-9999-ROW()*0.0000001,AC9-ROW()*0.0000001) | AK9: =IF(OR(AC9="",P9="",P9>MAX_PRICE),-9999-ROW()*0.0000001,AC9-ROW()*0.0000001) | AL9: =IF(AC9="",-9999-ROW()*0.0000001,X9*1000+AC9-ROW()*0.0000001) | AM9: =IF(AC9="",-9999-ROW()*0.0000001,Y9*1000+AC9-ROW()*0.0000001) | AN9: =IF(AND(OR(AD9="Maybe",AD9="Price Review"),AG9<>"Approved",AG9<>"Rejected"),IF(AC9="",0,AC9)-ROW()*0.0000001,-9999-ROW()*0.0000001) | AW9: =IF(OR(O9="",AV9=""),"",O9*AV9) | BE9: =IF(C9="","",IF(AND(ISNUMBER(P9),P9>MAX_PRICE),"Price too high",IF(AND(ISNUMBER(AB9),AB9<=2),"Quality risk",IF(AND(ISNUMBER(U9),U9<=2),"Aesthetic mismatch",IF(AY9="High","Too fragile",IF(AND(ISNUMBER(R9),R9<LOW_PROFIT_PCT),"Low profit",IF(AND(ISNUMBER(AT9),AT9>MOQ_WARNING),"MOQ too high",IF(OR(AD9="Maybe",AD9="Price Review"),"Needs partner review",IF(AD9="Buy","Good candidate",""))))))))) | BL9: =IF(C9="","",IF(AND(BG9="Yes",BH9="Yes",BI9="Yes",BJ9="Yes",BK9="Yes"),"Yes","No")) | BO9: =IF(OR(BM9="",BN9=""),"",BM9+BN9) | BQ9: =IF(OR(BP9="",BO9=""),"",BP9-BO9) | BR9: =IF(OR(BP9="",BP9=0,BQ9=""),"",BQ9/BP9) | BX9: =IF(OR(BT9="",BU9=""),"",BT9-BU9)
A10: =IF(C10="","","AYN-"&IFERROR(VLOOKUP(E10,CATEGORY_PREFIX_TABLE,2,FALSE),"OTH")&"-"&TEXT(ROW()-2,"0000")) | K10: =IF(I10="","",IF(J10="BDT",I10,IF(J10="USD",I10*USD_BDT,IF(J10="RMB",I10*RMB_BDT,"")))) | O10: =IF(K10="","",K10+IFERROR(L10,0)+(K10*IF(M10="",CUSTOMS_PCT,M10))+IF(N10="",MISC_FEE,N10)) | P10: =IF(O10="","",ROUND(O10*(1+MARKUP_PCT),-1)-1) | Q10: =IF(P10="","",P10-O10) | R10: =IF(OR(P10="",P10=0),"",Q10/P10) | AC10: =IF(COUNT(S10:AB10)<10,"",(S10*W_FEMININE+T10*W_TREND+U10*W_AESTHETIC+V10*W_STYLE+W10*W_LIGHT+X10*W_REELS+Y10*W_GIFT+Z10*W_PRICEFIT+AA10*W_DEMAND+AB10*W_QUALITY)/5*100) | AD10: =IF(P10="","",IF(P10>HARD_REJECT_PRICE,"Reject",IF(P10>MAX_PRICE,"Price Review",IF(AC10="","",IF(AND(AC10>=BUY_THRESHOLD,OR(AB10<=2,U10<=2)),"Maybe",IF(AC10>=BUY_THRESHOLD,"Buy",IF(AC10>=MAYBE_THRESHOLD,"Maybe","Reject"))))))) | AJ10: =IF(AC10="",-9999-ROW()*0.0000001,AC10-ROW()*0.0000001) | AK10: =IF(OR(AC10="",P10="",P10>MAX_PRICE),-9999-ROW()*0.0000001,AC10-ROW()*0.0000001) | AL10: =IF(AC10="",-9999-ROW()*0.0000001,X10*1000+AC10-ROW()*0.0000001) | AM10: =IF(AC10="",-9999-ROW()*0.0000001,Y10*1000+AC10-ROW()*0.0000001) | AN10: =IF(AND(OR(AD10="Maybe",AD10="Price Review"),AG10<>"Approved",AG10<>"Rejected"),IF(AC10="",0,AC10)-ROW()*0.0000001,-9999-ROW()*0.0000001) | AW10: =IF(OR(O10="",AV10=""),"",O10*AV10) | BE10: =IF(C10="","",IF(AND(ISNUMBER(P10),P10>MAX_PRICE),"Price too high",IF(AND(ISNUMBER(AB10),AB10<=2),"Quality risk",IF(AND(ISNUMBER(U10),U10<=2),"Aesthetic mismatch",IF(AY10="High","Too fragile",IF(AND(ISNUMBER(R10),R10<LOW_PROFIT_PCT),"Low profit",IF(AND(ISNUMBER(AT10),AT10>MOQ_WARNING),"MOQ too high",IF(OR(AD10="Maybe",AD10="Price Review"),"Needs partner review",IF(AD10="Buy","Good candidate",""))))))))) | BL10: =IF(C10="","",IF(AND(BG10="Yes",BH10="Yes",BI10="Yes",BJ10="Yes",BK10="Yes"),"Yes","No")) | BO10: =IF(OR(BM10="",BN10=""),"",BM10+BN10) | BQ10: =IF(OR(BP10="",BO10=""),"",BP10-BO10) | BR10: =IF(OR(BP10="",BP10=0,BQ10=""),"",BQ10/BP10) | BX10: =IF(OR(BT10="",BU10=""),"",BT10-BU10)
A11: =IF(C11="","","AYN-"&IFERROR(VLOOKUP(E11,CATEGORY_PREFIX_TABLE,2,FALSE),"OTH")&"-"&TEXT(ROW()-2,"0000")) | K11: =IF(I11="","",IF(J11="BDT",I11,IF(J11="USD",I11*USD_BDT,IF(J11="RMB",I11*RMB_BDT,"")))) | O11: =IF(K11="","",K11+IFERROR(L11,0)+(K11*IF(M11="",CUSTOMS_PCT,M11))+IF(N11="",MISC_FEE,N11)) | P11: =IF(O11="","",ROUND(O11*(1+MARKUP_PCT),-1)-1) | Q11: =IF(P11="","",P11-O11) | R11: =IF(OR(P11="",P11=0),"",Q11/P11) | AC11: =IF(COUNT(S11:AB11)<10,"",(S11*W_FEMININE+T11*W_TREND+U11*W_AESTHETIC+V11*W_STYLE+W11*W_LIGHT+X11*W_REELS+Y11*W_GIFT+Z11*W_PRICEFIT+AA11*W_DEMAND+AB11*W_QUALITY)/5*100) | AD11: =IF(P11="","",IF(P11>HARD_REJECT_PRICE,"Reject",IF(P11>MAX_PRICE,"Price Review",IF(AC11="","",IF(AND(AC11>=BUY_THRESHOLD,OR(AB11<=2,U11<=2)),"Maybe",IF(AC11>=BUY_THRESHOLD,"Buy",IF(AC11>=MAYBE_THRESHOLD,"Maybe","Reject"))))))) | AJ11: =IF(AC11="",-9999-ROW()*0.0000001,AC11-ROW()*0.0000001) | AK11: =IF(OR(AC11="",P11="",P11>MAX_PRICE),-9999-ROW()*0.0000001,AC11-ROW()*0.0000001) | AL11: =IF(AC11="",-9999-ROW()*0.0000001,X11*1000+AC11-ROW()*0.0000001) | AM11: =IF(AC11="",-9999-ROW()*0.0000001,Y11*1000+AC11-ROW()*0.0000001) | AN11: =IF(AND(OR(AD11="Maybe",AD11="Price Review"),AG11<>"Approved",AG11<>"Rejected"),IF(AC11="",0,AC11)-ROW()*0.0000001,-9999-ROW()*0.0000001) | AW11: =IF(OR(O11="",AV11=""),"",O11*AV11) | BE11: =IF(C11="","",IF(AND(ISNUMBER(P11),P11>MAX_PRICE),"Price too high",IF(AND(ISNUMBER(AB11),AB11<=2),"Quality risk",IF(AND(ISNUMBER(U11),U11<=2),"Aesthetic mismatch",IF(AY11="High","Too fragile",IF(AND(ISNUMBER(R11),R11<LOW_PROFIT_PCT),"Low profit",IF(AND(ISNUMBER(AT11),AT11>MOQ_WARNING),"MOQ too high",IF(OR(AD11="Maybe",AD11="Price Review"),"Needs partner review",IF(AD11="Buy","Good candidate",""))))))))) | BL11: =IF(C11="","",IF(AND(BG11="Yes",BH11="Yes",BI11="Yes",BJ11="Yes",BK11="Yes"),"Yes","No")) | BO11: =IF(OR(BM11="",BN11=""),"",BM11+BN11) | BQ11: =IF(OR(BP11="",BO11=""),"",BP11-BO11) | BR11: =IF(OR(BP11="",BP11=0,BQ11=""),"",BQ11/BP11) | BX11: =IF(OR(BT11="",BU11=""),"",BT11-BU11)
A12: =IF(C12="","","AYN-"&IFERROR(VLOOKUP(E12,CATEGORY_PREFIX_TABLE,2,FALSE),"OTH")&"-"&TEXT(ROW()-2,"0000")) | K12: =IF(I12="","",IF(J12="BDT",I12,IF(J12="USD",I12*USD_BDT,IF(J12="RMB",I12*RMB_BDT,"")))) | O12: =IF(K12="","",K12+IFERROR(L12,0)+(K12*IF(M12="",CUSTOMS_PCT,M12))+IF(N12="",MISC_FEE,N12)) | P12: =IF(O12="","",ROUND(O12*(1+MARKUP_PCT),-1)-1) | Q12: =IF(P12="","",P12-O12) | R12: =IF(OR(P12="",P12=0),"",Q12/P12) | AC12: =IF(COUNT(S12:AB12)<10,"",(S12*W_FEMININE+T12*W_TREND+U12*W_AESTHETIC+V12*W_STYLE+W12*W_LIGHT+X12*W_REELS+Y12*W_GIFT+Z12*W_PRICEFIT+AA12*W_DEMAND+AB12*W_QUALITY)/5*100) | AD12: =IF(P12="","",IF(P12>HARD_REJECT_PRICE,"Reject",IF(P12>MAX_PRICE,"Price Review",IF(AC12="","",IF(AND(AC12>=BUY_THRESHOLD,OR(AB12<=2,U12<=2)),"Maybe",IF(AC12>=BUY_THRESHOLD,"Buy",IF(AC12>=MAYBE_THRESHOLD,"Maybe","Reject"))))))) | AJ12: =IF(AC12="",-9999-ROW()*0.0000001,AC12-ROW()*0.0000001) | AK12: =IF(OR(AC12="",P12="",P12>MAX_PRICE),-9999-ROW()*0.0000001,AC12-ROW()*0.0000001) | AL12: =IF(AC12="",-9999-ROW()*0.0000001,X12*1000+AC12-ROW()*0.0000001) | AM12: =IF(AC12="",-9999-ROW()*0.0000001,Y12*1000+AC12-ROW()*0.0000001) | AN12: =IF(AND(OR(AD12="Maybe",AD12="Price Review"),AG12<>"Approved",AG12<>"Rejected"),IF(AC12="",0,AC12)-ROW()*0.0000001,-9999-ROW()*0.0000001) | AW12: =IF(OR(O12="",AV12=""),"",O12*AV12) | BE12: =IF(C12="","",IF(AND(ISNUMBER(P12),P12>MAX_PRICE),"Price too high",IF(AND(ISNUMBER(AB12),AB12<=2),"Quality risk",IF(AND(ISNUMBER(U12),U12<=2),"Aesthetic mismatch",IF(AY12="High","Too fragile",IF(AND(ISNUMBER(R12),R12<LOW_PROFIT_PCT),"Low profit",IF(AND(ISNUMBER(AT12),AT12>MOQ_WARNING),"MOQ too high",IF(OR(AD12="Maybe",AD12="Price Review"),"Needs partner review",IF(AD12="Buy","Good candidate",""))))))))) | BL12: =IF(C12="","",IF(AND(BG12="Yes",BH12="Yes",BI12="Yes",BJ12="Yes",BK12="Yes"),"Yes","No")) | BO12: =IF(OR(BM12="",BN12=""),"",BM12+BN12) | BQ12: =IF(OR(BP12="",BO12=""),"",BP12-BO12) | BR12: =IF(OR(BP12="",BP12=0,BQ12=""),"",BQ12/BP12) | BX12: =IF(OR(BT12="",BU12=""),"",BT12-BU12)
A13: =IF(C13="","","AYN-"&IFERROR(VLOOKUP(E13,CATEGORY_PREFIX_TABLE,2,FALSE),"OTH")&"-"&TEXT(ROW()-2,"0000")) | K13: =IF(I13="","",IF(J13="BDT",I13,IF(J13="USD",I13*USD_BDT,IF(J13="RMB",I13*RMB_BDT,"")))) | O13: =IF(K13="","",K13+IFERROR(L13,0)+(K13*IF(M13="",CUSTOMS_PCT,M13))+IF(N13="",MISC_FEE,N13)) | P13: =IF(O13="","",ROUND(O13*(1+MARKUP_PCT),-1)-1) | Q13: =IF(P13="","",P13-O13) | R13: =IF(OR(P13="",P13=0),"",Q13/P13) | AC13: =IF(COUNT(S13:AB13)<10,"",(S13*W_FEMININE+T13*W_TREND+U13*W_AESTHETIC+V13*W_STYLE+W13*W_LIGHT+X13*W_REELS+Y13*W_GIFT+Z13*W_PRICEFIT+AA13*W_DEMAND+AB13*W_QUALITY)/5*100) | AD13: =IF(P13="","",IF(P13>HARD_REJECT_PRICE,"Reject",IF(P13>MAX_PRICE,"Price Review",IF(AC13="","",IF(AND(AC13>=BUY_THRESHOLD,OR(AB13<=2,U13<=2)),"Maybe",IF(AC13>=BUY_THRESHOLD,"Buy",IF(AC13>=MAYBE_THRESHOLD,"Maybe","Reject"))))))) | AJ13: =IF(AC13="",-9999-ROW()*0.0000001,AC13-ROW()*0.0000001) | AK13: =IF(OR(AC13="",P13="",P13>MAX_PRICE),-9999-ROW()*0.0000001,AC13-ROW()*0.0000001) | AL13: =IF(AC13="",-9999-ROW()*0.0000001,X13*1000+AC13-ROW()*0.0000001) | AM13: =IF(AC13="",-9999-ROW()*0.0000001,Y13*1000+AC13-ROW()*0.0000001) | AN13: =IF(AND(OR(AD13="Maybe",AD13="Price Review"),AG13<>"Approved",AG13<>"Rejected"),IF(AC13="",0,AC13)-ROW()*0.0000001,-9999-ROW()*0.0000001) | AW13: =IF(OR(O13="",AV13=""),"",O13*AV13) | BE13: =IF(C13="","",IF(AND(ISNUMBER(P13),P13>MAX_PRICE),"Price too high",IF(AND(ISNUMBER(AB13),AB13<=2),"Quality risk",IF(AND(ISNUMBER(U13),U13<=2),"Aesthetic mismatch",IF(AY13="High","Too fragile",IF(AND(ISNUMBER(R13),R13<LOW_PROFIT_PCT),"Low profit",IF(AND(ISNUMBER(AT13),AT13>MOQ_WARNING),"MOQ too high",IF(OR(AD13="Maybe",AD13="Price Review"),"Needs partner review",IF(AD13="Buy","Good candidate",""))))))))) | BL13: =IF(C13="","",IF(AND(BG13="Yes",BH13="Yes",BI13="Yes",BJ13="Yes",BK13="Yes"),"Yes","No")) | BO13: =IF(OR(BM13="",BN13=""),"",BM13+BN13) | BQ13: =IF(OR(BP13="",BO13=""),"",BP13-BO13) | BR13: =IF(OR(BP13="",BP13=0,BQ13=""),"",BQ13/BP13) | BX13: =IF(OR(BT13="",BU13=""),"",BT13-BU13)
A14: =IF(C14="","","AYN-"&IFERROR(VLOOKUP(E14,CATEGORY_PREFIX_TABLE,2,FALSE),"OTH")&"-"&TEXT(ROW()-2,"0000")) | K14: =IF(I14="","",IF(J14="BDT",I14,IF(J14="USD",I14*USD_BDT,IF(J14="RMB",I14*RMB_BDT,"")))) | O14: =IF(K14="","",K14+IFERROR(L14,0)+(K14*IF(M14="",CUSTOMS_PCT,M14))+IF(N14="",MISC_FEE,N14)) | P14: =IF(O14="","",ROUND(O14*(1+MARKUP_PCT),-1)-1) | Q14: =IF(P14="","",P14-O14) | R14: =IF(OR(P14="",P14=0),"",Q14/P14) | AC14: =IF(COUNT(S14:AB14)<10,"",(S14*W_FEMININE+T14*W_TREND+U14*W_AESTHETIC+V14*W_STYLE+W14*W_LIGHT+X14*W_REELS+Y14*W_GIFT+Z14*W_PRICEFIT+AA14*W_DEMAND+AB14*W_QUALITY)/5*100) | AD14: =IF(P14="","",IF(P14>HARD_REJECT_PRICE,"Reject",IF(P14>MAX_PRICE,"Price Review",IF(AC14="","",IF(AND(AC14>=BUY_THRESHOLD,OR(AB14<=2,U14<=2)),"Maybe",IF(AC14>=BUY_THRESHOLD,"Buy",IF(AC14>=MAYBE_THRESHOLD,"Maybe","Reject"))))))) | AJ14: =IF(AC14="",-9999-ROW()*0.0000001,AC14-ROW()*0.0000001) | AK14: =IF(OR(AC14="",P14="",P14>MAX_PRICE),-9999-ROW()*0.0000001,AC14-ROW()*0.0000001) | AL14: =IF(AC14="",-9999-ROW()*0.0000001,X14*1000+AC14-ROW()*0.0000001) | AM14: =IF(AC14="",-9999-ROW()*0.0000001,Y14*1000+AC14-ROW()*0.0000001) | AN14: =IF(AND(OR(AD14="Maybe",AD14="Price Review"),AG14<>"Approved",AG14<>"Rejected"),IF(AC14="",0,AC14)-ROW()*0.0000001,-9999-ROW()*0.0000001) | AW14: =IF(OR(O14="",AV14=""),"",O14*AV14) | BE14: =IF(C14="","",IF(AND(ISNUMBER(P14),P14>MAX_PRICE),"Price too high",IF(AND(ISNUMBER(AB14),AB14<=2),"Quality risk",IF(AND(ISNUMBER(U14),U14<=2),"Aesthetic mismatch",IF(AY14="High","Too fragile",IF(AND(ISNUMBER(R14),R14<LOW_PROFIT_PCT),"Low profit",IF(AND(ISNUMBER(AT14),AT14>MOQ_WARNING),"MOQ too high",IF(OR(AD14="Maybe",AD14="Price Review"),"Needs partner review",IF(AD14="Buy","Good candidate",""))))))))) | BL14: =IF(C14="","",IF(AND(BG14="Yes",BH14="Yes",BI14="Yes",BJ14="Yes",BK14="Yes"),"Yes","No")) | BO14: =IF(OR(BM14="",BN14=""),"",BM14+BN14) | BQ14: =IF(OR(BP14="",BO14=""),"",BP14-BO14) | BR14: =IF(OR(BP14="",BP14=0,BQ14=""),"",BQ14/BP14) | BX14: =IF(OR(BT14="",BU14=""),"",BT14-BU14)
A15: =IF(C15="","","AYN-"&IFERROR(VLOOKUP(E15,CATEGORY_PREFIX_TABLE,2,FALSE),"OTH")&"-"&TEXT(ROW()-2,"0000")) | K15: =IF(I15="","",IF(J15="BDT",I15,IF(J15="USD",I15*USD_BDT,IF(J15="RMB",I15*RMB_BDT,"")))) | O15: =IF(K15="","",K15+IFERROR(L15,0)+(K15*IF(M15="",CUSTOMS_PCT,M15))+IF(N15="",MISC_FEE,N15)) | P15: =IF(O15="","",ROUND(O15*(1+MARKUP_PCT),-1)-1) | Q15: =IF(P15="","",P15-O15) | R15: =IF(OR(P15="",P15=0),"",Q15/P15) | AC15: =IF(COUNT(S15:AB15)<10,"",(S15*W_FEMININE+T15*W_TREND+U15*W_AESTHETIC+V15*W_STYLE+W15*W_LIGHT+X15*W_REELS+Y15*W_GIFT+Z15*W_PRICEFIT+AA15*W_DEMAND+AB15*W_QUALITY)/5*100) | AD15: =IF(P15="","",IF(P15>HARD_REJECT_PRICE,"Reject",IF(P15>MAX_PRICE,"Price Review",IF(AC15="","",IF(AND(AC15>=BUY_THRESHOLD,OR(AB15<=2,U15<=2)),"Maybe",IF(AC15>=BUY_THRESHOLD,"Buy",IF(AC15>=MAYBE_THRESHOLD,"Maybe","Reject"))))))) | AJ15: =IF(AC15="",-9999-ROW()*0.0000001,AC15-ROW()*0.0000001) | AK15: =IF(OR(AC15="",P15="",P15>MAX_PRICE),-9999-ROW()*0.0000001,AC15-ROW()*0.0000001) | AL15: =IF(AC15="",-9999-ROW()*0.0000001,X15*1000+AC15-ROW()*0.0000001) | AM15: =IF(AC15="",-9999-ROW()*0.0000001,Y15*1000+AC15-ROW()*0.0000001) | AN15: =IF(AND(OR(AD15="Maybe",AD15="Price Review"),AG15<>"Approved",AG15<>"Rejected"),IF(AC15="",0,AC15)-ROW()*0.0000001,-9999-ROW()*0.0000001) | AW15: =IF(OR(O15="",AV15=""),"",O15*AV15) | BE15: =IF(C15="","",IF(AND(ISNUMBER(P15),P15>MAX_PRICE),"Price too high",IF(AND(ISNUMBER(AB15),AB15<=2),"Quality risk",IF(AND(ISNUMBER(U15),U15<=2),"Aesthetic mismatch",IF(AY15="High","Too fragile",IF(AND(ISNUMBER(R15),R15<LOW_PROFIT_PCT),"Low profit",IF(AND(ISNUMBER(AT15),AT15>MOQ_WARNING),"MOQ too high",IF(OR(AD15="Maybe",AD15="Price Review"),"Needs partner review",IF(AD15="Buy","Good candidate",""))))))))) | BL15: =IF(C15="","",IF(AND(BG15="Yes",BH15="Yes",BI15="Yes",BJ15="Yes",BK15="Yes"),"Yes","No")) | BO15: =IF(OR(BM15="",BN15=""),"",BM15+BN15) | BQ15: =IF(OR(BP15="",BO15=""),"",BP15-BO15) | BR15: =IF(OR(BP15="",BP15=0,BQ15=""),"",BQ15/BP15) | BX15: =IF(OR(BT15="",BU15=""),"",BT15-BU15)
A16: =IF(C16="","","AYN-"&IFERROR(VLOOKUP(E16,CATEGORY_PREFIX_TABLE,2,FALSE),"OTH")&"-"&TEXT(ROW()-2,"0000")) | K16: =IF(I16="","",IF(J16="BDT",I16,IF(J16="USD",I16*USD_BDT,IF(J16="RMB",I16*RMB_BDT,"")))) | O16: =IF(K16="","",K16+IFERROR(L16,0)+(K16*IF(M16="",CUSTOMS_PCT,M16))+IF(N16="",MISC_FEE,N16)) | P16: =IF(O16="","",ROUND(O16*(1+MARKUP_PCT),-1)-1) | Q16: =IF(P16="","",P16-O16) | R16: =IF(OR(P16="",P16=0),"",Q16/P16) | AC16: =IF(COUNT(S16:AB16)<10,"",(S16*W_FEMININE+T16*W_TREND+U16*W_AESTHETIC+V16*W_STYLE+W16*W_LIGHT+X16*W_REELS+Y16*W_GIFT+Z16*W_PRICEFIT+AA16*W_DEMAND+AB16*W_QUALITY)/5*100) | AD16: =IF(P16="","",IF(P16>HARD_REJECT_PRICE,"Reject",IF(P16>MAX_PRICE,"Price Review",IF(AC16="","",IF(AND(AC16>=BUY_THRESHOLD,OR(AB16<=2,U16<=2)),"Maybe",IF(AC16>=BUY_THRESHOLD,"Buy",IF(AC16>=MAYBE_THRESHOLD,"Maybe","Reject"))))))) | AJ16: =IF(AC16="",-9999-ROW()*0.0000001,AC16-ROW()*0.0000001) | AK16: =IF(OR(AC16="",P16="",P16>MAX_PRICE),-9999-ROW()*0.0000001,AC16-ROW()*0.0000001) | AL16: =IF(AC16="",-9999-ROW()*0.0000001,X16*1000+AC16-ROW()*0.0000001) | AM16: =IF(AC16="",-9999-ROW()*0.0000001,Y16*1000+AC16-ROW()*0.0000001) | AN16: =IF(AND(OR(AD16="Maybe",AD16="Price Review"),AG16<>"Approved",AG16<>"Rejected"),IF(AC16="",0,AC16)-ROW()*0.0000001,-9999-ROW()*0.0000001) | AW16: =IF(OR(O16="",AV16=""),"",O16*AV16) | BE16: =IF(C16="","",IF(AND(ISNUMBER(P16),P16>MAX_PRICE),"Price too high",IF(AND(ISNUMBER(AB16),AB16<=2),"Quality risk",IF(AND(ISNUMBER(U16),U16<=2),"Aesthetic mismatch",IF(AY16="High","Too fragile",IF(AND(ISNUMBER(R16),R16<LOW_PROFIT_PCT),"Low profit",IF(AND(ISNUMBER(AT16),AT16>MOQ_WARNING),"MOQ too high",IF(OR(AD16="Maybe",AD16="Price Review"),"Needs partner review",IF(AD16="Buy","Good candidate",""))))))))) | BL16: =IF(C16="","",IF(AND(BG16="Yes",BH16="Yes",BI16="Yes",BJ16="Yes",BK16="Yes"),"Yes","No")) | BO16: =IF(OR(BM16="",BN16=""),"",BM16+BN16) | BQ16: =IF(OR(BP16="",BO16=""),"",BP16-BO16) | BR16: =IF(OR(BP16="",BP16=0,BQ16=""),"",BQ16/BP16) | BX16: =IF(OR(BT16="",BU16=""),"",BT16-BU16)
A17: =IF(C17="","","AYN-"&IFERROR(VLOOKUP(E17,CATEGORY_PREFIX_TABLE,2,FALSE),"OTH")&"-"&TEXT(ROW()-2,"0000")) | K17: =IF(I17="","",IF(J17="BDT",I17,IF(J17="USD",I17*USD_BDT,IF(J17="RMB",I17*RMB_BDT,"")))) | O17: =IF(K17="","",K17+IFERROR(L17,0)+(K17*IF(M17="",CUSTOMS_PCT,M17))+IF(N17="",MISC_FEE,N17)) | P17: =IF(O17="","",ROUND(O17*(1+MARKUP_PCT),-1)-1) | Q17: =IF(P17="","",P17-O17) | R17: =IF(OR(P17="",P17=0),"",Q17/P17) | AC17: =IF(COUNT(S17:AB17)<10,"",(S17*W_FEMININE+T17*W_TREND+U17*W_AESTHETIC+V17*W_STYLE+W17*W_LIGHT+X17*W_REELS+Y17*W_GIFT+Z17*W_PRICEFIT+AA17*W_DEMAND+AB17*W_QUALITY)/5*100) | AD17: =IF(P17="","",IF(P17>HARD_REJECT_PRICE,"Reject",IF(P17>MAX_PRICE,"Price Review",IF(AC17="","",IF(AND(AC17>=BUY_THRESHOLD,OR(AB17<=2,U17<=2)),"Maybe",IF(AC17>=BUY_THRESHOLD,"Buy",IF(AC17>=MAYBE_THRESHOLD,"Maybe","Reject"))))))) | AJ17: =IF(AC17="",-9999-ROW()*0.0000001,AC17-ROW()*0.0000001) | AK17: =IF(OR(AC17="",P17="",P17>MAX_PRICE),-9999-ROW()*0.0000001,AC17-ROW()*0.0000001) | AL17: =IF(AC17="",-9999-ROW()*0.0000001,X17*1000+AC17-ROW()*0.0000001) | AM17: =IF(AC17="",-9999-ROW()*0.0000001,Y17*1000+AC17-ROW()*0.0000001) | AN17: =IF(AND(OR(AD17="Maybe",AD17="Price Review"),AG17<>"Approved",AG17<>"Rejected"),IF(AC17="",0,AC17)-ROW()*0.0000001,-9999-ROW()*0.0000001) | AW17: =IF(OR(O17="",AV17=""),"",O17*AV17) | BE17: =IF(C17="","",IF(AND(ISNUMBER(P17),P17>MAX_PRICE),"Price too high",IF(AND(ISNUMBER(AB17),AB17<=2),"Quality risk",IF(AND(ISNUMBER(U17),U17<=2),"Aesthetic mismatch",IF(AY17="High","Too fragile",IF(AND(ISNUMBER(R17),R17<LOW_PROFIT_PCT),"Low profit",IF(AND(ISNUMBER(AT17),AT17>MOQ_WARNING),"MOQ too high",IF(OR(AD17="Maybe",AD17="Price Review"),"Needs partner review",IF(AD17="Buy","Good candidate",""))))))))) | BL17: =IF(C17="","",IF(AND(BG17="Yes",BH17="Yes",BI17="Yes",BJ17="Yes",BK17="Yes"),"Yes","No")) | BO17: =IF(OR(BM17="",BN17=""),"",BM17+BN17) | BQ17: =IF(OR(BP17="",BO17=""),"",BP17-BO17) | BR17: =IF(OR(BP17="",BP17=0,BQ17=""),"",BQ17/BP17) | BX17: =IF(OR(BT17="",BU17=""),"",BT17-BU17)
A18: =IF(C18="","","AYN-"&IFERROR(VLOOKUP(E18,CATEGORY_PREFIX_TABLE,2,FALSE),"OTH")&"-"&TEXT(ROW()-2,"0000")) | K18: =IF(I18="","",IF(J18="BDT",I18,IF(J18="USD",I18*USD_BDT,IF(J18="RMB",I18*RMB_BDT,"")))) | O18: =IF(K18="","",K18+IFERROR(L18,0)+(K18*IF(M18="",CUSTOMS_PCT,M18))+IF(N18="",MISC_FEE,N18)) | P18: =IF(O18="","",ROUND(O18*(1+MARKUP_PCT),-1)-1) | Q18: =IF(P18="","",P18-O18) | R18: =IF(OR(P18="",P18=0),"",Q18/P18) | AC18: =IF(COUNT(S18:AB18)<10,"",(S18*W_FEMININE+T18*W_TREND+U18*W_AESTHETIC+V18*W_STYLE+W18*W_LIGHT+X18*W_REELS+Y18*W_GIFT+Z18*W_PRICEFIT+AA18*W_DEMAND+AB18*W_QUALITY)/5*100) | AD18: =IF(P18="","",IF(P18>HARD_REJECT_PRICE,"Reject",IF(P18>MAX_PRICE,"Price Review",IF(AC18="","",IF(AND(AC18>=BUY_THRESHOLD,OR(AB18<=2,U18<=2)),"Maybe",IF(AC18>=BUY_THRESHOLD,"Buy",IF(AC18>=MAYBE_THRESHOLD,"Maybe","Reject"))))))) | AJ18: =IF(AC18="",-9999-ROW()*0.0000001,AC18-ROW()*0.0000001) | AK18: =IF(OR(AC18="",P18="",P18>MAX_PRICE),-9999-ROW()*0.0000001,AC18-ROW()*0.0000001) | AL18: =IF(AC18="",-9999-ROW()*0.0000001,X18*1000+AC18-ROW()*0.0000001) | AM18: =IF(AC18="",-9999-ROW()*0.0000001,Y18*1000+AC18-ROW()*0.0000001) | AN18: =IF(AND(OR(AD18="Maybe",AD18="Price Review"),AG18<>"Approved",AG18<>"Rejected"),IF(AC18="",0,AC18)-ROW()*0.0000001,-9999-ROW()*0.0000001) | AW18: =IF(OR(O18="",AV18=""),"",O18*AV18) | BE18: =IF(C18="","",IF(AND(ISNUMBER(P18),P18>MAX_PRICE),"Price too high",IF(AND(ISNUMBER(AB18),AB18<=2),"Quality risk",IF(AND(ISNUMBER(U18),U18<=2),"Aesthetic mismatch",IF(AY18="High","Too fragile",IF(AND(ISNUMBER(R18),R18<LOW_PROFIT_PCT),"Low profit",IF(AND(ISNUMBER(AT18),AT18>MOQ_WARNING),"MOQ too high",IF(OR(AD18="Maybe",AD18="Price Review"),"Needs partner review",IF(AD18="Buy","Good candidate",""))))))))) | BL18: =IF(C18="","",IF(AND(BG18="Yes",BH18="Yes",BI18="Yes",BJ18="Yes",BK18="Yes"),"Yes","No")) | BO18: =IF(OR(BM18="",BN18=""),"",BM18+BN18) | BQ18: =IF(OR(BP18="",BO18=""),"",BP18-BO18) | BR18: =IF(OR(BP18="",BP18=0,BQ18=""),"",BQ18/BP18) | BX18: =IF(OR(BT18="",BU18=""),"",BT18-BU18)
A19: =IF(C19="","","AYN-"&IFERROR(VLOOKUP(E19,CATEGORY_PREFIX_TABLE,2,FALSE),"OTH")&"-"&TEXT(ROW()-2,"0000")) | K19: =IF(I19="","",IF(J19="BDT",I19,IF(J19="USD",I19*USD_BDT,IF(J19="RMB",I19*RMB_BDT,"")))) | O19: =IF(K19="","",K19+IFERROR(L19,0)+(K19*IF(M19="",CUSTOMS_PCT,M19))+IF(N19="",MISC_FEE,N19)) | P19: =IF(O19="","",ROUND(O19*(1+MARKUP_PCT),-1)-1) | Q19: =IF(P19="","",P19-O19) | R19: =IF(OR(P19="",P19=0),"",Q19/P19) | AC19: =IF(COUNT(S19:AB19)<10,"",(S19*W_FEMININE+T19*W_TREND+U19*W_AESTHETIC+V19*W_STYLE+W19*W_LIGHT+X19*W_REELS+Y19*W_GIFT+Z19*W_PRICEFIT+AA19*W_DEMAND+AB19*W_QUALITY)/5*100) | AD19: =IF(P19="","",IF(P19>HARD_REJECT_PRICE,"Reject",IF(P19>MAX_PRICE,"Price Review",IF(AC19="","",IF(AND(AC19>=BUY_THRESHOLD,OR(AB19<=2,U19<=2)),"Maybe",IF(AC19>=BUY_THRESHOLD,"Buy",IF(AC19>=MAYBE_THRESHOLD,"Maybe","Reject"))))))) | AJ19: =IF(AC19="",-9999-ROW()*0.0000001,AC19-ROW()*0.0000001) | AK19: =IF(OR(AC19="",P19="",P19>MAX_PRICE),-9999-ROW()*0.0000001,AC19-ROW()*0.0000001) | AL19: =IF(AC19="",-9999-ROW()*0.0000001,X19*1000+AC19-ROW()*0.0000001) | AM19: =IF(AC19="",-9999-ROW()*0.0000001,Y19*1000+AC19-ROW()*0.0000001) | AN19: =IF(AND(OR(AD19="Maybe",AD19="Price Review"),AG19<>"Approved",AG19<>"Rejected"),IF(AC19="",0,AC19)-ROW()*0.0000001,-9999-ROW()*0.0000001) | AW19: =IF(OR(O19="",AV19=""),"",O19*AV19) | BE19: =IF(C19="","",IF(AND(ISNUMBER(P19),P19>MAX_PRICE),"Price too high",IF(AND(ISNUMBER(AB19),AB19<=2),"Quality risk",IF(AND(ISNUMBER(U19),U19<=2),"Aesthetic mismatch",IF(AY19="High","Too fragile",IF(AND(ISNUMBER(R19),R19<LOW_PROFIT_PCT),"Low profit",IF(AND(ISNUMBER(AT19),AT19>MOQ_WARNING),"MOQ too high",IF(OR(AD19="Maybe",AD19="Price Review"),"Needs partner review",IF(AD19="Buy","Good candidate",""))))))))) | BL19: =IF(C19="","",IF(AND(BG19="Yes",BH19="Yes",BI19="Yes",BJ19="Yes",BK19="Yes"),"Yes","No")) | BO19: =IF(OR(BM19="",BN19=""),"",BM19+BN19) | BQ19: =IF(OR(BP19="",BO19=""),"",BP19-BO19) | BR19: =IF(OR(BP19="",BP19=0,BQ19=""),"",BQ19/BP19) | BX19: =IF(OR(BT19="",BU19=""),"",BT19-BU19)
... A500: =IF(C500="","","AYN-"&IFERROR(VLOOKUP(E500,CATEGORY_PREFIX_TABLE,2,FALSE),"OTH")&"-"&TEXT(ROW()-2,"0000")) | K500: =IF(I500="","",IF(J500="BDT",I500,IF(J500="USD",I500*USD_BDT,IF(J500="RMB",I500*RMB_BDT,"")))) | O500: =IF(K500="","",K500+IFERROR(L500,0)+(K500*IF(M500="",CUSTOMS_PCT,M500))+IF(N500="",MISC_FEE,N500)) | P500: =IF(O500="","",ROUND(O500*(1+MARKUP_PCT),-1)-1) | Q500: =IF(P500="","",P500-O500) | R500: =IF(OR(P500="",P500=0),"",Q500/P500) | AC500: =IF(COUNT(S500:AB500)<10,"",(S500*W_FEMININE+T500*W_TREND+U500*W_AESTHETIC+V500*W_STYLE+W500*W_LIGHT+X500*W_REELS+Y500*W_GIFT+Z500*W_PRICEFIT+AA500*W_DEMAND+AB500*W_QUALITY)/5*100) | AD500: =IF(P500="","",IF(P500>HARD_REJECT_PRICE,"Reject",IF(P500>MAX_PRICE,"Price Review",IF(AC500="","",IF(AND(AC500>=BUY_THRESHOLD,OR(AB500<=2,U500<=2)),"Maybe",IF(AC500>=BUY_THRESHOLD,"Buy",IF(AC500>=MAYBE_THRESHOLD,"Maybe","Reject"))))))) | AJ500: =IF(AC500="",-9999-ROW()*0.0000001,AC500-ROW()*0.0000001) | AK500: =IF(OR(AC500="",P500="",P500>MAX_PRICE),-9999-ROW()*0.0000001,AC500-ROW()*0.0000001) | AL500: =IF(AC500="",-9999-ROW()*0.0000001,X500*1000+AC500-ROW()*0.0000001) | AM500: =IF(AC500="",-9999-ROW()*0.0000001,Y500*1000+AC500-ROW()*0.0000001) | AN500: =IF(AND(OR(AD500="Maybe",AD500="Price Review"),AG500<>"Approved",AG500<>"Rejected"),IF(AC500="",0,AC500)-ROW()*0.0000001,-9999-ROW()*0.0000001) | AW500: =IF(OR(O500="",AV500=""),"",O500*AV500) | BE500: =IF(C500="","",IF(AND(ISNUMBER(P500),P500>MAX_PRICE),"Price too high",IF(AND(ISNUMBER(AB500),AB500<=2),"Quality risk",IF(AND(ISNUMBER(U500),U500<=2),"Aesthetic mismatch",IF(AY500="High","Too fragile",IF(AND(ISNUMBER(R500),R500<LOW_PROFIT_PCT),"Low profit",IF(AND(ISNUMBER(AT500),AT500>MOQ_WARNING),"MOQ too high",IF(OR(AD500="Maybe",AD500="Price Review"),"Needs partner review",IF(AD500="Buy","Good candidate",""))))))))) | BL500: =IF(C500="","",IF(AND(BG500="Yes",BH500="Yes",BI500="Yes",BJ500="Yes",BK500="Yes"),"Yes","No")) | BO500: =IF(OR(BM500="",BN500=""),"",BM500+BN500) | BQ500: =IF(OR(BP500="",BO500=""),"",BP500-BO500) | BR500: =IF(OR(BP500="",BP500=0,BQ500=""),"",BQ500/BP500) | BX500: =IF(OR(BT500="",BU500=""),"",BT500-BU500)

Sheet Dashboard
A1: AAYNA PRODUCT SCOUT
A2: Reflect your everyday style.
A3: SOURCING DASHBOARD | R3: =IF('Product Tracker'!AD3="Buy",IF('Product Tracker'!AC3="",0,'Product Tracker'!AC3)-ROW()*0.0000001,-9999-ROW()*0.0000001) | S3: =IF('Product Tracker'!BL3="Yes",IF('Product Tracker'!AC3="",0,'Product Tracker'!AC3)-ROW()*0.0000001,-9999-ROW()*0.0000001) | T3: =IF(OR('Product Tracker'!AY3="High",'Product Tracker'!BA3="High",AND('Product Tracker'!AB3<>"",'Product Tracker'!AB3<=2)),IF('Product Tracker'!AC3="",0,'Product Tracker'!AC3)-ROW()*0.0000001,-9999-ROW()*0.0000001)
R4: =IF('Product Tracker'!AD4="Buy",IF('Product Tracker'!AC4="",0,'Product Tracker'!AC4)-ROW()*0.0000001,-9999-ROW()*0.0000001) | S4: =IF('Product Tracker'!BL4="Yes",IF('Product Tracker'!AC4="",0,'Product Tracker'!AC4)-ROW()*0.0000001,-9999-ROW()*0.0000001) | T4: =IF(OR('Product Tracker'!AY4="High",'Product Tracker'!BA4="High",AND('Product Tracker'!AB4<>"",'Product Tracker'!AB4<=2)),IF('Product Tracker'!AC4="",0,'Product Tracker'!AC4)-ROW()*0.0000001,-9999-ROW()*0.0000001)
A5: KPI OVERVIEW | R5: =IF('Product Tracker'!AD5="Buy",IF('Product Tracker'!AC5="",0,'Product Tracker'!AC5)-ROW()*0.0000001,-9999-ROW()*0.0000001) | S5: =IF('Product Tracker'!BL5="Yes",IF('Product Tracker'!AC5="",0,'Product Tracker'!AC5)-ROW()*0.0000001,-9999-ROW()*0.0000001) | T5: =IF(OR('Product Tracker'!AY5="High",'Product Tracker'!BA5="High",AND('Product Tracker'!AB5<>"",'Product Tracker'!AB5<=2)),IF('Product Tracker'!AC5="",0,'Product Tracker'!AC5)-ROW()*0.0000001,-9999-ROW()*0.0000001)
A6: TOTAL PRODUCTS | D6: BUY | G6: MAYBE | J6: PRICE REVIEW | R6: =IF('Product Tracker'!AD6="Buy",IF('Product Tracker'!AC6="",0,'Product Tracker'!AC6)-ROW()*0.0000001,-9999-ROW()*0.0000001) | S6: =IF('Product Tracker'!BL6="Yes",IF('Product Tracker'!AC6="",0,'Product Tracker'!AC6)-ROW()*0.0000001,-9999-ROW()*0.0000001) | T6: =IF(OR('Product Tracker'!AY6="High",'Product Tracker'!BA6="High",AND('Product Tracker'!AB6<>"",'Product Tracker'!AB6<=2)),IF('Product Tracker'!AC6="",0,'Product Tracker'!AC6)-ROW()*0.0000001,-9999-ROW()*0.0000001)
A7: =COUNTA('Product Tracker'!C3:C500) | D7: =COUNTIF('Product Tracker'!AD3:AD500,"Buy") | G7: =COUNTIF('Product Tracker'!AD3:AD500,"Maybe") | J7: =COUNTIF('Product Tracker'!AD3:AD500,"Price Review") | R7: =IF('Product Tracker'!AD7="Buy",IF('Product Tracker'!AC7="",0,'Product Tracker'!AC7)-ROW()*0.0000001,-9999-ROW()*0.0000001) | S7: =IF('Product Tracker'!BL7="Yes",IF('Product Tracker'!AC7="",0,'Product Tracker'!AC7)-ROW()*0.0000001,-9999-ROW()*0.0000001) | T7: =IF(OR('Product Tracker'!AY7="High",'Product Tracker'!BA7="High",AND('Product Tracker'!AB7<>"",'Product Tracker'!AB7<=2)),IF('Product Tracker'!AC7="",0,'Product Tracker'!AC7)-ROW()*0.0000001,-9999-ROW()*0.0000001)
R8: =IF('Product Tracker'!AD8="Buy",IF('Product Tracker'!AC8="",0,'Product Tracker'!AC8)-ROW()*0.0000001,-9999-ROW()*0.0000001) | S8: =IF('Product Tracker'!BL8="Yes",IF('Product Tracker'!AC8="",0,'Product Tracker'!AC8)-ROW()*0.0000001,-9999-ROW()*0.0000001) | T8: =IF(OR('Product Tracker'!AY8="High",'Product Tracker'!BA8="High",AND('Product Tracker'!AB8<>"",'Product Tracker'!AB8<=2)),IF('Product Tracker'!AC8="",0,'Product Tracker'!AC8)-ROW()*0.0000001,-9999-ROW()*0.0000001)
R9: =IF('Product Tracker'!AD9="Buy",IF('Product Tracker'!AC9="",0,'Product Tracker'!AC9)-ROW()*0.0000001,-9999-ROW()*0.0000001) | S9: =IF('Product Tracker'!BL9="Yes",IF('Product Tracker'!AC9="",0,'Product Tracker'!AC9)-ROW()*0.0000001,-9999-ROW()*0.0000001) | T9: =IF(OR('Product Tracker'!AY9="High",'Product Tracker'!BA9="High",AND('Product Tracker'!AB9<>"",'Product Tracker'!AB9<=2)),IF('Product Tracker'!AC9="",0,'Product Tracker'!AC9)-ROW()*0.0000001,-9999-ROW()*0.0000001)
A10: REJECT | D10: WEBSITE READY | G10: HIGH RISK | J10: APPROVED COST | R10: =IF('Product Tracker'!AD10="Buy",IF('Product Tracker'!AC10="",0,'Product Tracker'!AC10)-ROW()*0.0000001,-9999-ROW()*0.0000001) | S10: =IF('Product Tracker'!BL10="Yes",IF('Product Tracker'!AC10="",0,'Product Tracker'!AC10)-ROW()*0.0000001,-9999-ROW()*0.0000001) | T10: =IF(OR('Product Tracker'!AY10="High",'Product Tracker'!BA10="High",AND('Product Tracker'!AB10<>"",'Product Tracker'!AB10<=2)),IF('Product Tracker'!AC10="",0,'Product Tracker'!AC10)-ROW()*0.0000001,-9999-ROW()*0.0000001)
A11: =COUNTIF('Product Tracker'!AD3:AD500,"Reject") | D11: =COUNTIF('Product Tracker'!BL3:BL500,"Yes") | G11: =SUMPRODUCT(--(('Product Tracker'!AY3:AY500="High")+('Product Tracker'!BA3:BA500="High")+(('Product Tracker'!AB3:AB500<>"")*('Product Tracker'!AB3:AB500<=2))>0)) | J11: =SUMIF('Product Tracker'!AG3:AG500,"Approved",'Product Tracker'!AW3:AW500) | R11: =IF('Product Tracker'!AD11="Buy",IF('Product Tracker'!AC11="",0,'Product Tracker'!AC11)-ROW()*0.0000001,-9999-ROW()*0.0000001) | S11: =IF('Product Tracker'!BL11="Yes",IF('Product Tracker'!AC11="",0,'Product Tracker'!AC11)-ROW()*0.0000001,-9999-ROW()*0.0000001) | T11: =IF(OR('Product Tracker'!AY11="High",'Product Tracker'!BA11="High",AND('Product Tracker'!AB11<>"",'Product Tracker'!AB11<=2)),IF('Product Tracker'!AC11="",0,'Product Tracker'!AC11)-ROW()*0.0000001,-9999-ROW()*0.0000001)
R12: =IF('Product Tracker'!AD12="Buy",IF('Product Tracker'!AC12="",0,'Product Tracker'!AC12)-ROW()*0.0000001,-9999-ROW()*0.0000001) | S12: =IF('Product Tracker'!BL12="Yes",IF('Product Tracker'!AC12="",0,'Product Tracker'!AC12)-ROW()*0.0000001,-9999-ROW()*0.0000001) | T12: =IF(OR('Product Tracker'!AY12="High",'Product Tracker'!BA12="High",AND('Product Tracker'!AB12<>"",'Product Tracker'!AB12<=2)),IF('Product Tracker'!AC12="",0,'Product Tracker'!AC12)-ROW()*0.0000001,-9999-ROW()*0.0000001)
R13: =IF('Product Tracker'!AD13="Buy",IF('Product Tracker'!AC13="",0,'Product Tracker'!AC13)-ROW()*0.0000001,-9999-ROW()*0.0000001) | S13: =IF('Product Tracker'!BL13="Yes",IF('Product Tracker'!AC13="",0,'Product Tracker'!AC13)-ROW()*0.0000001,-9999-ROW()*0.0000001) | T13: =IF(OR('Product Tracker'!AY13="High",'Product Tracker'!BA13="High",AND('Product Tracker'!AB13<>"",'Product Tracker'!AB13<=2)),IF('Product Tracker'!AC13="",0,'Product Tracker'!AC13)-ROW()*0.0000001,-9999-ROW()*0.0000001)
A14: BUDGET OVERVIEW | R14: =IF('Product Tracker'!AD14="Buy",IF('Product Tracker'!AC14="",0,'Product Tracker'!AC14)-ROW()*0.0000001,-9999-ROW()*0.0000001) | S14: =IF('Product Tracker'!BL14="Yes",IF('Product Tracker'!AC14="",0,'Product Tracker'!AC14)-ROW()*0.0000001,-9999-ROW()*0.0000001) | T14: =IF(OR('Product Tracker'!AY14="High",'Product Tracker'!BA14="High",AND('Product Tracker'!AB14<>"",'Product Tracker'!AB14<=2)),IF('Product Tracker'!AC14="",0,'Product Tracker'!AC14)-ROW()*0.0000001,-9999-ROW()*0.0000001)
A15: APPROVED PURCHASE COST | D15: REMAINING BUDGET | G15: APPROVED QUANTITY | J15: APPROVED PRODUCTS | R15: =IF('Product Tracker'!AD15="Buy",IF('Product Tracker'!AC15="",0,'Product Tracker'!AC15)-ROW()*0.0000001,-9999-ROW()*0.0000001) | S15: =IF('Product Tracker'!BL15="Yes",IF('Product Tracker'!AC15="",0,'Product Tracker'!AC15)-ROW()*0.0000001,-9999-ROW()*0.0000001) | T15: =IF(OR('Product Tracker'!AY15="High",'Product Tracker'!BA15="High",AND('Product Tracker'!AB15<>"",'Product Tracker'!AB15<=2)),IF('Product Tracker'!AC15="",0,'Product Tracker'!AC15)-ROW()*0.0000001,-9999-ROW()*0.0000001)
A16: =SUMIF('Product Tracker'!AG3:AG500,"Approved",'Product Tracker'!AW3:AW500) | D16: =MONTHLY_BUDGET-A16 | G16: =SUMIF('Product Tracker'!AG3:AG500,"Approved",'Product Tracker'!AV3:AV500) | J16: =COUNTIF('Product Tracker'!AG3:AG500,"Approved") | R16: =IF('Product Tracker'!AD16="Buy",IF('Product Tracker'!AC16="",0,'Product Tracker'!AC16)-ROW()*0.0000001,-9999-ROW()*0.0000001) | S16: =IF('Product Tracker'!BL16="Yes",IF('Product Tracker'!AC16="",0,'Product Tracker'!AC16)-ROW()*0.0000001,-9999-ROW()*0.0000001) | T16: =IF(OR('Product Tracker'!AY16="High",'Product Tracker'!BA16="High",AND('Product Tracker'!AB16<>"",'Product Tracker'!AB16<=2)),IF('Product Tracker'!AC16="",0,'Product Tracker'!AC16)-ROW()*0.0000001,-9999-ROW()*0.0000001)
R17: =IF('Product Tracker'!AD17="Buy",IF('Product Tracker'!AC17="",0,'Product Tracker'!AC17)-ROW()*0.0000001,-9999-ROW()*0.0000001) | S17: =IF('Product Tracker'!BL17="Yes",IF('Product Tracker'!AC17="",0,'Product Tracker'!AC17)-ROW()*0.0000001,-9999-ROW()*0.0000001) | T17: =IF(OR('Product Tracker'!AY17="High",'Product Tracker'!BA17="High",AND('Product Tracker'!AB17<>"",'Product Tracker'!AB17<=2)),IF('Product Tracker'!AC17="",0,'Product Tracker'!AC17)-ROW()*0.0000001,-9999-ROW()*0.0000001)
A18: BUDGET USED | D18: =IF(MONTHLY_BUDGET=0,"",A16/MONTHLY_BUDGET) | R18: =IF('Product Tracker'!AD18="Buy",IF('Product Tracker'!AC18="",0,'Product Tracker'!AC18)-ROW()*0.0000001,-9999-ROW()*0.0000001) | S18: =IF('Product Tracker'!BL18="Yes",IF('Product Tracker'!AC18="",0,'Product Tracker'!AC18)-ROW()*0.0000001,-9999-ROW()*0.0000001) | T18: =IF(OR('Product Tracker'!AY18="High",'Product Tracker'!BA18="High",AND('Product Tracker'!AB18<>"",'Product Tracker'!AB18<=2)),IF('Product Tracker'!AC18="",0,'Product Tracker'!AC18)-ROW()*0.0000001,-9999-ROW()*0.0000001)
R19: =IF('Product Tracker'!AD19="Buy",IF('Product Tracker'!AC19="",0,'Product Tracker'!AC19)-ROW()*0.0000001,-9999-ROW()*0.0000001) | S19: =IF('Product Tracker'!BL19="Yes",IF('Product Tracker'!AC19="",0,'Product Tracker'!AC19)-ROW()*0.0000001,-9999-ROW()*0.0000001) | T19: =IF(OR('Product Tracker'!AY19="High",'Product Tracker'!BA19="High",AND('Product Tracker'!AB19<>"",'Product Tracker'!AB19<=2)),IF('Product Tracker'!AC19="",0,'Product Tracker'!AC19)-ROW()*0.0000001,-9999-ROW()*0.0000001)
A20: TOP PRODUCTS TO BUY | R20: =IF('Product Tracker'!AD20="Buy",IF('Product Tracker'!AC20="",0,'Product Tracker'!AC20)-ROW()*0.0000001,-9999-ROW()*0.0000001) | S20: =IF('Product Tracker'!BL20="Yes",IF('Product Tracker'!AC20="",0,'Product Tracker'!AC20)-ROW()*0.0000001,-9999-ROW()*0.0000001) | T20: =IF(OR('Product Tracker'!AY20="High",'Product Tracker'!BA20="High",AND('Product Tracker'!AB20<>"",'Product Tracker'!AB20<=2)),IF('Product Tracker'!AC20="",0,'Product Tracker'!AC20)-ROW()*0.0000001,-9999-ROW()*0.0000001)
A21: Rank | B21: Product Name | F21: SKU | H21: Score | I21: Decision | K21: Suggested Price | R21: =IF('Product Tracker'!AD21="Buy",IF('Product Tracker'!AC21="",0,'Product Tracker'!AC21)-ROW()*0.0000001,-9999-ROW()*0.0000001) | S21: =IF('Product Tracker'!BL21="Yes",IF('Product Tracker'!AC21="",0,'Product Tracker'!AC21)-ROW()*0.0000001,-9999-ROW()*0.0000001) | T21: =IF(OR('Product Tracker'!AY21="High",'Product Tracker'!BA21="High",AND('Product Tracker'!AB21<>"",'Product Tracker'!AB21<=2)),IF('Product Tracker'!AC21="",0,'Product Tracker'!AC21)-ROW()*0.0000001,-9999-ROW()*0.0000001)
A22: 1 | B22: =IF(LARGE($R$3:$R$500,1)>-9000,IFERROR(INDEX('Product Tracker'!$C$3:$C$500,MATCH(LARGE($R$3:$R$500,1),$R$3:$R$500,0)),""),"") | F22: =IF(LARGE($R$3:$R$500,1)>-9000,IFERROR(INDEX('Product Tracker'!$A$3:$A$500,MATCH(LARGE($R$3:$R$500,1),$R$3:$R$500,0)),""),"") | H22: =IF(LARGE($R$3:$R$500,1)>-9000,IFERROR(INDEX('Product Tracker'!$AC$3:$AC$500,MATCH(LARGE($R$3:$R$500,1),$R$3:$R$500,0)),""),"") | I22: =IF(LARGE($R$3:$R$500,1)>-9000,IFERROR(INDEX('Product Tracker'!$AD$3:$AD$500,MATCH(LARGE($R$3:$R$500,1),$R$3:$R$500,0)),""),"") | K22: =IF(LARGE($R$3:$R$500,1)>-9000,IFERROR(INDEX('Product Tracker'!$P$3:$P$500,MATCH(LARGE($R$3:$R$500,1),$R$3:$R$500,0)),""),"") | R22: =IF('Product Tracker'!AD22="Buy",IF('Product Tracker'!AC22="",0,'Product Tracker'!AC22)-ROW()*0.0000001,-9999-ROW()*0.0000001) | S22: =IF('Product Tracker'!BL22="Yes",IF('Product Tracker'!AC22="",0,'Product Tracker'!AC22)-ROW()*0.0000001,-9999-ROW()*0.0000001) | T22: =IF(OR('Product Tracker'!AY22="High",'Product Tracker'!BA22="High",AND('Product Tracker'!AB22<>"",'Product Tracker'!AB22<=2)),IF('Product Tracker'!AC22="",0,'Product Tracker'!AC22)-ROW()*0.0000001,-9999-ROW()*0.0000001)
A23: 2 | B23: =IF(LARGE($R$3:$R$500,2)>-9000,IFERROR(INDEX('Product Tracker'!$C$3:$C$500,MATCH(LARGE($R$3:$R$500,2),$R$3:$R$500,0)),""),"") | F23: =IF(LARGE($R$3:$R$500,2)>-9000,IFERROR(INDEX('Product Tracker'!$A$3:$A$500,MATCH(LARGE($R$3:$R$500,2),$R$3:$R$500,0)),""),"") | H23: =IF(LARGE($R$3:$R$500,2)>-9000,IFERROR(INDEX('Product Tracker'!$AC$3:$AC$500,MATCH(LARGE($R$3:$R$500,2),$R$3:$R$500,0)),""),"") | I23: =IF(LARGE($R$3:$R$500,2)>-9000,IFERROR(INDEX('Product Tracker'!$AD$3:$AD$500,MATCH(LARGE($R$3:$R$500,2),$R$3:$R$500,0)),""),"") | K23: =IF(LARGE($R$3:$R$500,2)>-9000,IFERROR(INDEX('Product Tracker'!$P$3:$P$500,MATCH(LARGE($R$3:$R$500,2),$R$3:$R$500,0)),""),"") | R23: =IF('Product Tracker'!AD23="Buy",IF('Product Tracker'!AC23="",0,'Product Tracker'!AC23)-ROW()*0.0000001,-9999-ROW()*0.0000001) | S23: =IF('Product Tracker'!BL23="Yes",IF('Product Tracker'!AC23="",0,'Product Tracker'!AC23)-ROW()*0.0000001,-9999-ROW()*0.0000001) | T23: =IF(OR('Product Tracker'!AY23="High",'Product Tracker'!BA23="High",AND('Product Tracker'!AB23<>"",'Product Tracker'!AB23<=2)),IF('Product Tracker'!AC23="",0,'Product Tracker'!AC23)-ROW()*0.0000001,-9999-ROW()*0.0000001)
A24: 3 | B24: =IF(LARGE($R$3:$R$500,3)>-9000,IFERROR(INDEX('Product Tracker'!$C$3:$C$500,MATCH(LARGE($R$3:$R$500,3),$R$3:$R$500,0)),""),"") | F24: =IF(LARGE($R$3:$R$500,3)>-9000,IFERROR(INDEX('Product Tracker'!$A$3:$A$500,MATCH(LARGE($R$3:$R$500,3),$R$3:$R$500,0)),""),"") | H24: =IF(LARGE($R$3:$R$500,3)>-9000,IFERROR(INDEX('Product Tracker'!$AC$3:$AC$500,MATCH(LARGE($R$3:$R$500,3),$R$3:$R$500,0)),""),"") | I24: =IF(LARGE($R$3:$R$500,3)>-9000,IFERROR(INDEX('Product Tracker'!$AD$3:$AD$500,MATCH(LARGE($R$3:$R$500,3),$R$3:$R$500,0)),""),"") | K24: =IF(LARGE($R$3:$R$500,3)>-9000,IFERROR(INDEX('Product Tracker'!$P$3:$P$500,MATCH(LARGE($R$3:$R$500,3),$R$3:$R$500,0)),""),"") | R24: =IF('Product Tracker'!AD24="Buy",IF('Product Tracker'!AC24="",0,'Product Tracker'!AC24)-ROW()*0.0000001,-9999-ROW()*0.0000001) | S24: =IF('Product Tracker'!BL24="Yes",IF('Product Tracker'!AC24="",0,'Product Tracker'!AC24)-ROW()*0.0000001,-9999-ROW()*0.0000001) | T24: =IF(OR('Product Tracker'!AY24="High",'Product Tracker'!BA24="High",AND('Product Tracker'!AB24<>"",'Product Tracker'!AB24<=2)),IF('Product Tracker'!AC24="",0,'Product Tracker'!AC24)-ROW()*0.0000001,-9999-ROW()*0.0000001)
A25: 4 | B25: =IF(LARGE($R$3:$R$500,4)>-9000,IFERROR(INDEX('Product Tracker'!$C$3:$C$500,MATCH(LARGE($R$3:$R$500,4),$R$3:$R$500,0)),""),"") | F25: =IF(LARGE($R$3:$R$500,4)>-9000,IFERROR(INDEX('Product Tracker'!$A$3:$A$500,MATCH(LARGE($R$3:$R$500,4),$R$3:$R$500,0)),""),"") | H25: =IF(LARGE($R$3:$R$500,4)>-9000,IFERROR(INDEX('Product Tracker'!$AC$3:$AC$500,MATCH(LARGE($R$3:$R$500,4),$R$3:$R$500,0)),""),"") | I25: =IF(LARGE($R$3:$R$500,4)>-9000,IFERROR(INDEX('Product Tracker'!$AD$3:$AD$500,MATCH(LARGE($R$3:$R$500,4),$R$3:$R$500,0)),""),"") | K25: =IF(LARGE($R$3:$R$500,4)>-9000,IFERROR(INDEX('Product Tracker'!$P$3:$P$500,MATCH(LARGE($R$3:$R$500,4),$R$3:$R$500,0)),""),"") | R25: =IF('Product Tracker'!AD25="Buy",IF('Product Tracker'!AC25="",0,'Product Tracker'!AC25)-ROW()*0.0000001,-9999-ROW()*0.0000001) | S25: =IF('Product Tracker'!BL25="Yes",IF('Product Tracker'!AC25="",0,'Product Tracker'!AC25)-ROW()*0.0000001,-9999-ROW()*0.0000001) | T25: =IF(OR('Product Tracker'!AY25="High",'Product Tracker'!BA25="High",AND('Product Tracker'!AB25<>"",'Product Tracker'!AB25<=2)),IF('Product Tracker'!AC25="",0,'Product Tracker'!AC25)-ROW()*0.0000001,-9999-ROW()*0.0000001)
A26: 5 | B26: =IF(LARGE($R$3:$R$500,5)>-9000,IFERROR(INDEX('Product Tracker'!$C$3:$C$500,MATCH(LARGE($R$3:$R$500,5),$R$3:$R$500,0)),""),"") | F26: =IF(LARGE($R$3:$R$500,5)>-9000,IFERROR(INDEX('Product Tracker'!$A$3:$A$500,MATCH(LARGE($R$3:$R$500,5),$R$3:$R$500,0)),""),"") | H26: =IF(LARGE($R$3:$R$500,5)>-9000,IFERROR(INDEX('Product Tracker'!$AC$3:$AC$500,MATCH(LARGE($R$3:$R$500,5),$R$3:$R$500,0)),""),"") | I26: =IF(LARGE($R$3:$R$500,5)>-9000,IFERROR(INDEX('Product Tracker'!$AD$3:$AD$500,MATCH(LARGE($R$3:$R$500,5),$R$3:$R$500,0)),""),"") | K26: =IF(LARGE($R$3:$R$500,5)>-9000,IFERROR(INDEX('Product Tracker'!$P$3:$P$500,MATCH(LARGE($R$3:$R$500,5),$R$3:$R$500,0)),""),"") | R26: =IF('Product Tracker'!AD26="Buy",IF('Product Tracker'!AC26="",0,'Product Tracker'!AC26)-ROW()*0.0000001,-9999-ROW()*0.0000001) | S26: =IF('Product Tracker'!BL26="Yes",IF('Product Tracker'!AC26="",0,'Product Tracker'!AC26)-ROW()*0.0000001,-9999-ROW()*0.0000001) | T26: =IF(OR('Product Tracker'!AY26="High",'Product Tracker'!BA26="High",AND('Product Tracker'!AB26<>"",'Product Tracker'!AB26<=2)),IF('Product Tracker'!AC26="",0,'Product Tracker'!AC26)-ROW()*0.0000001,-9999-ROW()*0.0000001)
